Workbook

Sheet Data
C1: 1 | D1: 2 | E1: 3 | F1: 4 | M1: Mon | N1: Tue | O1: Wed | P1: Thu | Q1: Fri | R1: Mon | S1: Tue | T1: Wed | U1: Thu | V1: Fri | W1: Mon | X1: Tue | Y1: Wed | Z1: Thu | AA1: Fri | AB1: Mon | AC1: Tue | AD1: Wed | AE1: Thu | AF1: Fri | AG1: Mon | AH1: Tue | AI1: Wed
A2: S.No | B2: Cohort | C2: Enrollment number | D2: Name of the Student | E2: Specialization | F2: MobileNo | G2: Mail IDs | H2: Gender | I2: Name According to Bank | J2: Parent Mobile NO | K2: DOB | L2: Age | M2: 1 | N2: 2 | O2: 3 | P2: 4 | Q2: 5 | R2: 8 | S2: 9 | T2: 10 | U2: 11 | V2: 12 | W2: 15 | X2: 16 | Y2: 17 | Z2: 18 | AA2: 19 | AB2: 22 | AC2: 23 | AD2: 24 | AE2: 25 | AF2: 26 | AG2: 29 | AH2: 30 | AI2: 31
A3: 1 | B3: 1 | C3: 0223CPIT001 | D3: NIKITHA ADULA | E3: ITES | F3: 6399221384 | G3: nikitha.itesites@gmail.com | H3: Female | I3: =D3 -> NIKITHA ADULA | J3: 2120339506 | K3: 01.01.2005 | L3: 18 | M3: P | N3: P | O3: A | P3: P | Q3: P | R3: P | S3: P | T3: P | U3: A | V3: P | W3: P | X3: A | Y3: P | Z3: P | AA3: P | AB3: P | AC3: P | AD3: P | AE3: P | AF3: P | AG3: L | AH3: P | AI3: P
A4: 2 | B4: 1 | C4: 0223CPIT002 | D4: ADULA LIKHITHA | E4: Full Stack | F4: 8732960724 | G4: adulalikitha.fullstack@gmail.com | H4: Female | I4: =D4 -> ADULA LIKHITHA | J4: 2573691990 | K4: 06.10.2002 | L4: 21 | M4: P | N4: =CHOOSE(RANDBETWEEN(1,3),"P","A","L") -> L | AE4: P | AF4: P | AG4: L | AH4: A | AI4: L
A5: 3 | B5: 3 | C5: 0223CPIT003 | D5: AKASH RAJPOOT | E5: Full Stack | F5: 3928683138 | G5: akashrajpoot.fullstack@gmail.com | H5: Male | I5: =D5 -> AKASH RAJPOOT | J5: 8436624675 | K5: 09.06.2004 | L5: 19 | M5: P
A6: 4 | B6: 3 | C6: 0223CPIT004 | D6: ALOK KUMAR | E6: Full Stack | F6: 6302977515 | G6: alokkumar.fullstack@gmail.com | H6: Male | I6: =D6 -> ALOK KUMAR | J6: 2124694089 | K6: 28.03.2004 | L6: 19 | M6: P
A7: 5 | B7: 1 | C7: 0223CPIT005 | D7: AYUSHMAN SINGH BAGHEL | E7: Full Stack | F7: 3285643454 | G7: ayushmansinghbaghel.fullstack@gmail.com | H7: Male | I7: =D7 -> AYUSHMAN SINGH BAGHEL | J7: 6858212965 | K7: 02.12.2005 | L7: 18 | M7: A
A8: 6 | B8: 3 | C8: 0223CPIT006 | D8: B SANDEEP ROY | E8: ITES | F8: 6204804746 | G8: bsandeeproy.itesites@gmail.com | H8: Male | I8: =D8 -> B SANDEEP ROY | J8: 1456755625 | K8: 10.07.1998 | L8: 25 | M8: P
A9: 7 | B9: 3 | C9: 0223CPIT007 | D9: B. SRINIVASULU | E9: Full Stack | F9: 8402592334 | G9: bsrinivasulu.fullstack@gmail.com | H9: Male | I9: =D9 -> B. SRINIVASULU | J9: 1716014472 | K9: 16.06.2005 | L9: 18 | M9: P
A10: 8 | B10: 1 | C10: 0223CPIT008 | D10: BAIRI PRATHYUSH | E10: Full Stack | F10: 1770577932 | G10: bairiprathyush.fullstack@gmail.com | H10: Male | I10: =D10 -> BAIRI PRATHYUSH | J10: 2915576343 | K10: 02.08.2002 | L10: 21 | M10: P
A11: 9 | B11: 1 | C11: 0223CPIT009 | D11: BANDAPALLI GANGABHAVANI | E11: ITES | F11: 1087593685 | G11: bandapalligangabhavani.itesites@gmail.com | H11: Female | I11: =D11 -> BANDAPALLI GANGABHAVANI | J11: 7625492200 | K11: 10.11.2001 | L11: 22 | M11: A
A12: 10 | B12: 2 | C12: 0223CPIT010 | D12: BURRI VINITHA | E12: Full Stack | F12: 1693682470 | G12: burrivinitha.fullstack@gmail.com | H12: Female | I12: =D12 -> BURRI VINITHA | J12: 5262777453 | K12: 12.09.2004 | L12: 19 | M12: P
A13: 11 | B13: 2 | C13: 0223CPIT011 | D13: CHANDRA SAMPATH KUMAR | E13: Full Stack | F13: 1821308586 | G13: chandrasampathkumar.fullstack@gmail.com | H13: Male | I13: =D13 -> CHANDRA SAMPATH KUMAR | J13: 3313353085 | K13: 09.12.2002 | L13: 21 | M13: P
A14: 12 | B14: 1 | C14: 0223CPIT012 | D14: CHINNAKOTLA SURYA TEJA | E14: Full Stack | F14: 1683546545 | G14: chinnakotlasuryateja.fullstack@gmail.com | H14: Male | I14: =D14 -> CHINNAKOTLA SURYA TEJA | J14: 6225939300 | K14: 23.03.2001 | L14: 22 | M14: P
A15: 13 | B15: 3 | C15: 0223CPIT013 | D15: DASARI VIMALA | E15: Full Stack | F15: 5506439807 | G15: dasarivimala.fullstack@gmail.com | H15: Female | I15: =D15 -> DASARI VIMALA | J15: 5760440421 | K15: 01.10.2003 | L15: 20 | M15: P
A16: 14 | B16: 1 | C16: 0223CPIT014 | D16: DEVALLA DEEPAK | E16: ITES | F16: 3565997600 | G16: devalladeepak.itesites@gmail.com | H16: Male | I16: =D16 -> DEVALLA DEEPAK | J16: 8490923938 | K16: 30.01.2006 | L16: 17 | M16: P
... A34: 32 | B34: 1 | C34: 0223CPIT032 | D34: M. BALAJI | E34: ITES | F34: 7375541777 | G34: mbalaji.itesites@gmail.com | H34: Male | I34: =D34 -> M. BALAJI | J34: 2479994830 | K34: 29.07.2004 | L34: 19 | M34: P
A35: 33 | B35: 3 | C35: 0223CPIT033 | D35: MADHI VAISHNAVI | E35: ITES | F35: 2307603936 | G35: madhivaishnavi.itesites@gmail.com | H35: Female | I35: =D35 -> MADHI VAISHNAVI | J35: 2464662826 | K35: 37853 | L35: 20 | M35: P
A36: 34 | B36: 2 | C36: 0223CPIT034 | D36: MANDALOJU NAGALAXMI | E36: Full Stack | F36: 7539961295 | G36: mandalojunagalaxmi.fullstack@gmail.com | H36: Female | I36: =D36 -> MANDALOJU NAGALAXMI | J36: 7329763453 | K36: 15.07.2005 | L36: 18 | M36: P
A37: 35 | B37: 1 | C37: 0223CPIT035 | D37: MANIKYALA RAMADEVI | E37: Full Stack | F37: 8714929594 | G37: manikyalaramadevi.fullstack@gmail.com | H37: Female | I37: =D37 -> MANIKYALA RAMADEVI | J37: 1027318203 | K37: 10.07.2005 | L37: 18 | M37: P
A38: 36 | B38: 3 | C38: 0223CPIT036 | D38: MASKA PAVANI | E38: ITES | F38: 6748495954 | G38: maskapavani.itesites@gmail.com | H38: Female | I38: =D38 -> MASKA PAVANI | J38: 4012125534 | K38: 04.04.2006 | L38: 17 | M38: P
A39: 37 | B39: 3 | C39: 0223CPIT037 | D39: MEGHAGNI MUKHERJEE | E39: Full Stack | F39: 5598318903 | G39: meghagnimukherjee.fullstack@gmail.com | H39: Female | I39: =D39 -> MEGHAGNI MUKHERJEE | J39: 8606299440 | K39: 14.09.2005 | L39: 18 | M39: P
A40: 38 | B40: 1 | C40: 0223CPIT038 | D40: N LAXMI NARASIMHA | E40: Full Stack | F40: 5366755536 | G40: nlaxminarasimha.fullstack@gmail.com | H40: Male | I40: =D40 -> N LAXMI NARASIMHA | J40: 4099577077 | K40: 10.06.2005 | L40: 18 | M40: P
A41: 39 | B41: 3 | C41: 0223CPIT039 | D41: NANAPURAJ LAHARIKA | E41: ITES | F41: 5685425899 | G41: nanapurajlaharika.itesites@gmail.com | H41: Female | I41: =D41 -> NANAPURAJ LAHARIKA | J41: 3700957702 | K41: 15.04.2003 | L41: 20 | M41: P
A42: 40 | B42: 3 | C42: 0223CPIT040 | D42: NARRA VENKATA SAI | E42: ITES | F42: 8546891943 | G42: narravenkatasai.itesites@gmail.com | H42: Male | I42: =D42 -> NARRA VENKATA SAI | J42: 1351607642 | K42: 02.10.2002 | L42: 21 | M42: P
A43: 41 | B43: 3 | C43: 0223CPIT041 | D43: NAVUDU TEJESH | E43: ITES | F43: 7905481507 | G43: navudutejesh.itesites@gmail.com | H43: Male | I43: =D43 -> NAVUDU TEJESH | J43: 4584578764 | K43: 30.11.2005 | L43: 18 | M43: P
A44: 42 | B44: 2 | C44: 0223CPIT042 | D44: PALLEY SHRAVANI | E44: ITES | F44: 5681445328 | G44: palleyshravani.itesites@gmail.com | H44: Female | I44: =D44 -> PALLEY SHRAVANI | J44: 7661428150 | K44: 38337 | L44: 19 | M44: P
A45: 43 | B45: 2 | C45: 0223CPIT043 | D45: PAPAKANTI RAJU | E45: Full Stack | F45: 1576469041 | G45: papakantiraju.fullstack@gmail.com | H45: Male | I45: =D45 -> PAPAKANTI RAJU | J45: 3324864700 | K45: 02.10.2001 | L45: 22 | M45: P
A46: 44 | B46: 2 | C46: 0223CPIT044 | D46: PRATAPAGIRI NEELAKANTA SASTRY | E46: Full Stack | F46: 7244391357 | G46: pratapagirineelakantasastry.fullstack@gmail.com | H46: Male | I46: =D46 -> PRATAPAGIRI NEELAKANTA SASTRY | J46: 1344765434 | K46: 26.06.1999 | L46: 24 | M46: P
A47: 45 | B47: 1 | C47: 0223CPIT045 | D47: PRAVEEN RAJPOOT | E47: Full Stack | F47: 5713887644 | G47: praveenrajpoot.fullstack@gmail.com | H47: Male | I47: =D47 -> PRAVEEN RAJPOOT | J47: 8922958342 | K47: 04.06.2004 | L47: 19 | M47: P
A48: 46 | B48: 2 | C48: 0223CPIT046 | D48: R. VIGNESH | E48: ITES | F48: 4360003876 | G48: rvignesh.itesites@gmail.com | H48: Male | I48: =D48 -> R. VIGNESH | J48: 6311928736 | K48: 13.10.2004 | L48: 19 | M48: P
A49: 47 | B49: 2 | C49: 0223CPIT047 | D49: RACHAMANDUGU AJAYKUMAR | E49: Full Stack | F49: 6232183694 | G49: rachamanduguajaykumar.fullstack@gmail.com | H49: Male | I49: =D49 -> RACHAMANDUGU AJAYKUMAR | J49: 1358146481 | K49: 09.09.2004 | L49: 19 | M49: P
A50: 48 | B50: 3 | C50: 0223CPIT048 | D50: REVALLI NAGESHWARI | E50: Full Stack | F50: 6682877186 | G50: revallinageshwari.fullstack@gmail.com | H50: Female | I50: =D50 -> REVALLI NAGESHWARI | J50: 7997007047 | K50: 10.04.2003 | L50: 20 | M50: A
A51: 49 | B51: 3 | C51: 0223CPIT049 | D51: ROHIT REDDY | E51: ITES | F51: 8911831176 | G51: rohitreddy.itesites@gmail.com | H51: Male | I51: =D51 -> ROHIT REDDY | J51: 6665134788 | K51: 25.12.2005 | L51: 18 | M51: P
A52: 50 | B52: 3 | C52: 0223CPIT050 | D52: RUCHI RANJAN | E52: Full Stack | F52: 5328455783 | G52: ruchiranjan.fullstack@gmail.com | H52: Female | I52: =D52 -> RUCHI RANJAN | J52: 1065242166 | K52: 02.02.2005 | L52: 18 | M52: A
A53: 51 | B53: 1 | C53: 0223CPIT051 | D53: SHAIK FAHAD | E53: ITES | F53: 4825148027 | G53: shaikfahad.itesites@gmail.com | H53: Male | I53: =D53 -> SHAIK FAHAD | J53: 1828010878 | K53: 13.09.2004 | L53: 19 | M53: P
A54: 52 | B54: 3 | C54: 0223CPIT052 | D54: SHAIK SAMEER AHMED | E54: Full Stack | F54: 3228331930 | G54: shaiksameerahmed.fullstack@gmail.com | H54: Male | I54: =D54 -> SHAIK SAMEER AHMED | J54: 6717092554 | K54: 26.12.2003 | L54: 20 | M54: A
A55: 53 | B55: 1 | C55: 0223CPIT053 | D55: SHEJUL BALAJI RAMESHWAR | E55: Full Stack | F55: 7158666834 | G55: shejulbalajirameshwar.fullstack@gmail.com | H55: Male | I55: =D55 -> SHEJUL BALAJI RAMESHWAR | J55: 7178012275 | K55: 23.09.2003 | L55: 20 | M55: P
A56: 54 | B56: 2 | C56: 0223CPIT054 | D56: SHOAIB AKHTAR | E56: Full Stack | F56: 7998839021 | G56: shoaibakhtar.fullstack@gmail.com | H56: Male | I56: =D56 -> SHOAIB AKHTAR | J56: 1247692282 | K56: 05.06.2004 | L56: 19 | M56: A
... A79: 77 | B79: 1 | C79: 0223CPIT077 | D79: YARRA NAVYA SAHITHI | E79: Full Stack | F79: 6927479136 | G79: yarranavyasahithi.fullstack@gmail.com | H79: Female | I79: =D79 -> YARRA NAVYA SAHITHI | J79: 7539369224 | K79: 10.10.2002 | L79: 21 | M79: P
...

Sheet VLOOKUP
D4: Enrollment number | E4: Name of the Student | F4: Specialization
D5: 0223CPIT013 | E5: =VLOOKUP(D5,Data!$C$3:$F$82,2,FALSE) -> DASARI VIMALA | F5: =VLOOKUP(D5,Data!$C$3:$F$83,3,FALSE) -> Full Stack

Sheet HData
A1: Enrollment number | B1: 0223CPIT001 | C1: 0223CPIT002 | D1: 0223CPIT003 | E1: 0223CPIT004 | F1: 0223CPIT005 | G1: 0223CPIT006 | H1: 0223CPIT007 | I1: 0223CPIT008 | J1: 0223CPIT009 | K1: 0223CPIT010 | L1: 0223CPIT011 | M1: 0223CPIT012 | N1: 0223CPIT013 | O1: 0223CPIT014 | P1: 0223CPIT015 | Q1: 0223CPIT016 | R1: 0223CPIT017 | S1: 0223CPIT018 | T1: 0223CPIT019 | U1: 0223CPIT020 | V1: 0223CPIT021 | W1: 0223CPIT022 | X1: 0223CPIT023 | Y1: 0223CPIT024 | Z1: 0223CPIT025 | AA1: 0223CPIT026 | AB1: 0223CPIT027 | AC1: 0223CPIT028 | AD1: 0223CPIT029 | AE1: 0223CPIT030 | AF1: 0223CPIT031 | AG1: 0223CPIT032 | AH1: 0223CPIT033 | AI1: 0223CPIT034 | AJ1: 0223CPIT035 | AK1: 0223CPIT036 | AL1: 0223CPIT037 | AM1: 0223CPIT038 | AN1: 0223CPIT039 | AO1: 0223CPIT040 | AP1: 0223CPIT041 | AQ1: 0223CPIT042 | AR1: 0223CPIT043 | AS1: 0223CPIT044 | AT1: 0223CPIT045 | AU1: 0223CPIT046 | AV1: 0223CPIT047 | AW1: 0223CPIT048 | AX1: 0223CPIT049 | AY1: 0223CPIT050 | AZ1: 0223CPIT051 | BA1: 0223CPIT052 | BB1: 0223CPIT053 | BC1: 0223CPIT054 | BD1: 0223CPIT055 | BE1: 0223CPIT056 | BF1: 0223CPIT057 | BG1: 0223CPIT058 | BH1: 0223CPIT059 | BI1: 0223CPIT060 | BJ1: 0223CPIT061 | BK1: 0223CPIT062 | BL1: 0223CPIT063 | BM1: 0223CPIT064 | BN1: 0223CPIT065 | BO1: 0223CPIT066 | BP1: 0223CPIT067 | BQ1: 0223CPIT068 | BR1: 0223CPIT069 | BS1: 0223CPIT070 | BT1: 0223CPIT071 | BU1: 0223CPIT072 | BV1: 0223CPIT073 | BW1: 0223CPIT074 | BX1: 0223CPIT075 | BY1: 0223CPIT076 | BZ1: 0223CPIT077 | CA1: 0223CPIT078 | CB1: 0223CPIT079 | CC1: 0223CPIT080 | CD1: 123
A2: Name of the Student | B2: NIKITHA ADULA | C2: ADULA LIKHITHA | D2: AKASH RAJPOOT | E2: ALOK KUMAR | F2: AYUSHMAN SINGH BAGHEL | G2: B SANDEEP ROY | H2: B. SRINIVASULU | I2: BAIRI PRATHYUSH | J2: BANDAPALLI GANGABHAVANI | K2: BURRI VINITHA | L2: CHANDRA SAMPATH KUMAR | M2: CHINNAKOTLA SURYA TEJA | N2: DASARI VIMALA | O2: DEVALLA DEEPAK | P2: DEVKATHE KOMAL | Q2: EERAMMAGARI RAVITEJA | R2: ELLENDULA SUPRIYA | S2: GADIYARAM VARSHA | T2: GAIKWAD SRUSHTI | U2: GAJJELA GIRI | V2: GARAPATI GAYATHRI | W2: GOLI SAI LOKESH | X2: GURRAM YAMINI | Y2: HARI OM RAI | Z2: JADHAV YOGESH DHARAMSIGH | AA2: K. SANTOSHI | AB2: KALIGOTA NIHARIKA | AC2: KALPANA KODARI | AD2: KANCHA AKASH | AE2: KASTURI SAI MAHESH | AF2: LOVE TIWARI | AG2: M. BALAJI | AH2: MADHI VAISHNAVI | AI2: MANDALOJU NAGALAXMI | AJ2: MANIKYALA RAMADEVI | AK2: MASKA PAVANI | AL2: MEGHAGNI MUKHERJEE | AM2: N LAXMI NARASIMHA | AN2: NANAPURAJ LAHARIKA | AO2: NARRA VENKATA SAI | AP2: NAVUDU TEJESH | AQ2: PALLEY SHRAVANI | AR2: PAPAKANTI RAJU | AS2: PRATAPAGIRI NEELAKANTA SASTRY | AT2: PRAVEEN RAJPOOT | AU2: R. VIGNESH | AV2: RACHAMANDUGU AJAYKUMAR | AW2: REVALLI NAGESHWARI | AX2: ROHIT REDDY | AY2: RUCHI RANJAN | AZ2: SHAIK FAHAD | BA2: SHAIK SAMEER AHMED | BB2: SHEJUL BALAJI RAMESHWAR | BC2: SHOAIB AKHTAR | BD2: SINGAM KRISHNA VENI | BE2: SINGUDASU PALLAVI | BF2: SUBHASHIS PAL | BG2: SUJEET KUMAR | BH2: SURUCHI RANJAN | BI2: SUVENDU KHATUA | BJ2: SYED ABDUL HAKEEM | BK2: SYED ABDUL HALEEM | BL2: SYED ADIL | BM2: VELUPULA SUNIL KUMAR | BN2: BALA CHARY | BO2: BANDARI SRUJANA | BP2: DURGA PRASAD | BQ2: K PAVANI | BR2: M KOMAL RAJ | BS2: MEDI SANGEETHA | BT2: N.PARAMESH | BU2: NAGA CHANDU V | BV2: S SAMEER | BW2: SALVADI VENKATESH | BX2: UPPUNUTHALA PURUSHOTHAM | BY2: VINAY KUMAR | BZ2: YARRA NAVYA SAHITHI | CA2: M. Aravind | CB2: Surya Kiran | CC2: B Aravind
A3: Specialization | B3: ITES | C3: Full Stack | D3: Full Stack | E3: Full Stack | F3: Full Stack | G3: ITES | H3: Full Stack | I3: Full Stack | J3: ITES | K3: Full Stack | L3: Full Stack | M3: Full Stack | N3: Full Stack | O3: ITES | P3: Full Stack | Q3: Full Stack | R3: ITES | S3: Full Stack | T3: Full Stack | U3: ITES | V3: ITES | W3: Full Stack | X3: Full Stack | Y3: Full Stack | Z3: Full Stack | AA3: Full Stack | AB3: ITES | AC3: Full Stack | AD3: Full Stack | AE3: Full Stack | AF3: Full Stack | AG3: ITES | AH3: ITES | AI3: Full Stack | AJ3: Full Stack | AK3: ITES | AL3: Full Stack | AM3: Full Stack | AN3: ITES | AO3: ITES | AP3: ITES | AQ3: ITES | AR3: Full Stack | AS3: Full Stack | AT3: Full Stack | AU3: ITES | AV3: Full Stack | AW3: Full Stack | AX3: ITES | AY3: Full Stack | AZ3: ITES | BA3: Full Stack | BB3: Full Stack | BC3: Full Stack | BD3: Full Stack | BE3: Full Stack | BF3: ITES | BG3: Full Stack | BH3: Full Stack | BI3: ITES | BJ3: Full Stack | BK3: Full Stack | BL3: ITES | BM3: Full Stack | BN3: ITES | BO3: Full Stack | BP3: Full Stack | BQ3: Full Stack | BR3: ITES | BS3: Full Stack | BT3: Full Stack | BU3: ITES | BV3: Full Stack | BW3: ITES | BX3: ITES | BY3: Full Stack | BZ3: Full Stack | CA3: Full Stack | CB3: Full Stack | CC3: Full Stack
A4: MobileNo | B4: 6399221384 | C4: 8732960724 | D4: 3928683138 | E4: 6302977515 | F4: 3285643454 | G4: 6204804746 | H4: 8402592334 | I4: 1770577932 | J4: 1087593685 | K4: 1693682470 | L4: 1821308586 | M4: 1683546545 | N4: 5506439807 | O4: 3565997600 | P4: 2685014153 | Q4: 8144007188 | R4: 5451418853 | S4: 2352093828 | T4: 4851546652 | U4: 6604423032 | V4: 4267924443 | W4: 2776428499 | X4: 2344591250 | Y4: 4564000793 | Z4: 7831800139 | AA4: 1359937879 | AB4: 8357059907 | AC4: 8195300576 | AD4: 3908490120 | AE4: 6654686097 | AF4: 3176554504 | AG4: 7375541777 | AH4: 2307603936 | AI4: 7539961295 | AJ4: 8714929594 | AK4: 6748495954 | AL4: 5598318903 | AM4: 5366755536 | AN4: 5685425899 | AO4: 8546891943 | AP4: 7905481507 | AQ4: 5681445328 | AR4: 1576469041 | AS4: 7244391357 | AT4: 5713887644 | AU4: 4360003876 | AV4: 6232183694 | AW4: 6682877186 | AX4: 8911831176 | AY4: 5328455783 | AZ4: 4825148027 | BA4: 3228331930 | BB4: 7158666834 | BC4: 7998839021 | BD4: 8550635195 | BE4: 8733465367 | BF4: 6153044829 | BG4: 4496254693 | BH4: 2881088394 | BI4: 3401449282 | BJ4: 4405995363 | BK4: 2219599156 | BL4: 3482112190 | BM4: 8411360361 | BN4: 2842414479 | BO4: 5876113945 | BP4: 4273126076 | BQ4: 8077085042 | BR4: 8112643867 | BS4: 3685782386 | BT4: 6205596324 | BU4: 6578497608 | BV4: 2602080020 | BW4: 8796416295 | BX4: 5978571640 | BY4: 5716170881 | BZ4: 6927479136 | CA4: 8625176197 | CB4: 3221738150 | CC4: 2217423855
A5: Mail IDs | B5: nikitha.itesites@gmail.com | C5: adulalikitha.fullstack@gmail.com | D5: akashrajpoot.fullstack@gmail.com | E5: alokkumar.fullstack@gmail.com | F5: ayushmansinghbaghel.fullstack@gmail.com | G5: bsandeeproy.itesites@gmail.com | H5: bsrinivasulu.fullstack@gmail.com | I5: bairiprathyush.fullstack@gmail.com | J5: bandapalligangabhavani.itesites@gmail.com | K5: burrivinitha.fullstack@gmail.com | L5: chandrasampathkumar.fullstack@gmail.com | M5: chinnakotlasuryateja.fullstack@gmail.com | N5: dasarivimala.fullstack@gmail.com | O5: devalladeepak.itesites@gmail.com | P5: devkathekomal.fullstack@gmail.com | Q5: eerammagariraviteja.fullstack@gmail.com | R5: ellendulasupriya.itesites@gmail.com | S5: gadiyaramvarsha.fullstack@gmail.com | T5: gaikwadsrushti.fullstack@gmail.com | U5: gajjelagiri.itesites@gmail.com | V5: garapatigayathri.itesites@gmail.com | W5: golisailokesh.fullstack@gmail.com | X5: gurramyamini.fullstack@gmail.com | Y5: hariomrai.fullstack@gmail.com | Z5: jadhavyogeshdharamsigh.fullstack@gmail.com | AA5: ksantoshi.fullstack@gmail.com | AB5: kaligotaniharika.itesites@gmail.com | AC5: kalpanakodari.fullstack@gmail.com | AD5: kanchaakash.fullstack@gmail.com | AE5: kasturisaimahesh.fullstack@gmail.com | AF5: lovetiwari.fullstack@gmail.com | AG5: mbalaji.itesites@gmail.com | AH5: madhivaishnavi.itesites@gmail.com | AI5: mandalojunagalaxmi.fullstack@gmail.com | AJ5: manikyalaramadevi.fullstack@gmail.com | AK5: maskapavani.itesites@gmail.com | AL5: meghagnimukherjee.fullstack@gmail.com | AM5: nlaxminarasimha.fullstack@gmail.com | AN5: nanapurajlaharika.itesites@gmail.com | AO5: narravenkatasai.itesites@gmail.com | AP5: navudutejesh.itesites@gmail.com | AQ5: palleyshravani.itesites@gmail.com | AR5: papakantiraju.fullstack@gmail.com | AS5: pratapagirineelakantasastry.fullstack@gmail.com | AT5: praveenrajpoot.fullstack@gmail.com | AU5: rvignesh.itesites@gmail.com | AV5: rachamanduguajaykumar.fullstack@gmail.com | AW5: revallinageshwari.fullstack@gmail.com | AX5: rohitreddy.itesites@gmail.com | AY5: ruchiranjan.fullstack@gmail.com | AZ5: shaikfahad.itesites@gmail.com | BA5: shaiksameerahmed.fullstack@gmail.com | BB5: shejulbalajirameshwar.fullstack@gmail.com | BC5: shoaibakhtar.fullstack@gmail.com | BD5: singamkrishnaveni.fullstack@gmail.com | BE5: singudasupallavi.fullstack@gmail.com | BF5: subhashispal.itesites@gmail.com | BG5: sujeetkumar.fullstack@gmail.com | BH5: suruchiranjan.fullstack@gmail.com | BI5: suvendukhatua.itesites@gmail.com | BJ5: syedabdulhakeem.fullstack@gmail.com | BK5: syedabdulhaleem.fullstack@gmail.com | BL5: syedadil.itesites@gmail.com | BM5: velupulasunilkumar.fullstack@gmail.com | BN5: balachary.itesites@gmail.com | BO5: bandarisrujana.fullstack@gmail.com | BP5: durgaprasad.fullstack@gmail.com | BQ5: kpavani.fullstack@gmail.com | BR5: mkomalraj.itesites@gmail.com | BS5: medisangeetha.fullstack@gmail.com | BT5: nparamesh.fullstack@gmail.com | BU5: nagachanduv.itesites@gmail.com | BV5: ssameer.fullstack@gmail.com | BW5: salvadivenkatesh.itesites@gmail.com | BX5: uppunuthalapurushotham.itesites@gmail.com | BY5: vinaykumar.fullstack@gmail.com | BZ5: yarranavyasahithi.fullstack@gmail.com | CA5: maravind.fullstack@gmail.com | CB5: suryakiran.fullstack@gmail.com | CC5: baravind.fullstack@gmail.com
A6: Gender | B6: Female | C6: Female | D6: Male | E6: Male | F6: Male | G6: Male | H6: Male | I6: Male | J6: Female | K6: Female | L6: Male | M6: Male | N6: Female | O6: Male | P6: Female | Q6: Male | R6: Female | S6: Female | T6: Female | U6: Male | V6: Female | W6: Male | X6: Female | Y6: Male | Z6: Male | AA6: Female | AB6: Female | AC6: Female | AD6: Male | AE6: Male | AF6: Male | AG6: Male | AH6: Female | AI6: Female | AJ6: Female | AK6: Female | AL6: Female | AM6: Male | AN6: Female | AO6: Male | AP6: Male | AQ6: Female | AR6: Male | AS6: Male | AT6: Male | AU6: Male | AV6: Male | AW6: Female | AX6: Male | AY6: Female | AZ6: Male | BA6: Male | BB6: Male | BC6: Male | BD6: Female | BE6: Female | BF6: Male | BG6: Male | BH6: Female | BI6: Male | BJ6: Male | BK6: Male | BL6: Male | BM6: Male | BN6: Male | BO6: Female | BP6: Male | BQ6: Female | BR6: Male | BS6: Female | BT6: Male | BU6: Male | BV6: Male | BW6: Male | BX6: Male | BY6: Male | BZ6: Female | CA6: Male | CB6: Male | CC6: Male

Sheet HLOOKUP
F5: Enrollment number | G5: Name of the Student | H5: Specialization
F6: 0223CPIT015 | G6: =HLOOKUP(F6,HData!$B$1:$CD$6,2,FALSE) -> DEVKATHE KOMAL | H6: =HLOOKUP(F6,HData!$B$1:$CD$6,3,FALSE) -> Full Stack

Sheet INDEX
A1: Enrollment number | B1: Name of the Student | C1: Specialization | D1: MobileNo | E1: Mail IDs | F1: Gender
A2: 0223CPIT001 | B2: NIKITHA ADULA | C2: ITES | D2: 6399221384 | E2: nikitha.itesites@gmail.com | F2: Female | G2: Row and column | H2: =INDEX($A$2:$F$82,2,2) -> ADULA LIKHITHA
A3: 0223CPIT002 | B3: ADULA LIKHITHA | C3: Full Stack | D3: 8732960724 | E3: adulalikitha.fullstack@gmail.com | F3: Female | G3: Row | H3: =INDEX($E$2:$E$81,2) -> adulalikitha.fullstack@gmail.com
A4: 0223CPIT003 | B4: AKASH RAJPOOT | C4: Full Stack | D4: 3928683138 | E4: akashrajpoot.fullstack@gmail.com | F4: Male
A5: 0223CPIT004 | B5: ALOK KUMAR | C5: Full Stack | D5: 6302977515 | E5: alokkumar.fullstack@gmail.com | F5: Male | M5: Name of the Student | N5: NIKITHA ADULA | O5: ADULA LIKHITHA | P5: AKASH RAJPOOT | Q5: ALOK KUMAR
A6: 0223CPIT005 | B6: AYUSHMAN SINGH BAGHEL | C6: Full Stack | D6: 3285643454 | E6: ayushmansinghbaghel.fullstack@gmail.com | F6: Male | M6: Specialization | N6: ITES | O6: Full Stack | P6: Full Stack | Q6: Full Stack
A7: 0223CPIT006 | B7: B SANDEEP ROY | C7: ITES | D7: 6204804746 | E7: bsandeeproy.itesites@gmail.com | F7: Male | M7: MobileNo | N7: 6399221384 | O7: 8732960724 | P7: 3928683138 | Q7: 6302977515
A8: 0223CPIT007 | B8: B. SRINIVASULU | C8: Full Stack | D8: 8402592334 | E8: bsrinivasulu.fullstack@gmail.com | F8: Male | M8: Mail IDs | N8: nikitha.itesites@gmail.com | O8: adulalikitha.fullstack@gmail.com | P8: akashrajpoot.fullstack@gmail.com | Q8: alokkumar.fullstack@gmail.com
A9: 0223CPIT008 | B9: BAIRI PRATHYUSH | C9: Full Stack | D9: 1770577932 | E9: bairiprathyush.fullstack@gmail.com | F9: Male | M9: Gender | N9: Female | O9: Female | P9: Male | Q9: Male
A10: 0223CPIT009 | B10: BANDAPALLI GANGABHAVANI | C10: ITES | D10: 1087593685 | E10: bandapalligangabhavani.itesites@gmail.com | F10: Female
A11: 0223CPIT010 | B11: BURRI VINITHA | C11: Full Stack | D11: 1693682470 | E11: burrivinitha.fullstack@gmail.com | F11: Female
A12: 0223CPIT011 | B12: CHANDRA SAMPATH KUMAR | C12: Full Stack | D12: 1821308586 | E12: chandrasampathkumar.fullstack@gmail.com | F12: Male | L12: Row And Column | M12: =INDEX($N$5:$Q$9,1,2) -> ADULA LIKHITHA
A13: 0223CPIT012 | B13: CHINNAKOTLA SURYA TEJA | C13: Full Stack | D13: 1683546545 | E13: chinnakotlasuryateja.fullstack@gmail.com | F13: Male | L13: Row | M13: =INDEX($N$5:$Q$5,2) -> ADULA LIKHITHA
A14: 0223CPIT013 | B14: DASARI VIMALA | C14: Full Stack | D14: 5506439807 | E14: dasarivimala.fullstack@gmail.com | F14: Female
A15: 0223CPIT014 | B15: DEVALLA DEEPAK | C15: ITES | D15: 3565997600 | E15: devalladeepak.itesites@gmail.com | F15: Male
A16: 0223CPIT015 | B16: DEVKATHE KOMAL | C16: Full Stack | D16: 2685014153 | E16: devkathekomal.fullstack@gmail.com | F16: Female
A17: 0223CPIT016 | B17: EERAMMAGARI RAVITEJA | C17: Full Stack | D17: 8144007188 | E17: eerammagariraviteja.fullstack@gmail.com | F17: Male
A18: 0223CPIT017 | B18: ELLENDULA SUPRIYA | C18: ITES | D18: 5451418853 | E18: ellendulasupriya.itesites@gmail.com | F18: Female
A19: 0223CPIT018 | B19: GADIYARAM VARSHA | C19: Full Stack | D19: 2352093828 | E19: gadiyaramvarsha.fullstack@gmail.com | F19: Female
A20: 0223CPIT019 | B20: GAIKWAD SRUSHTI | C20: Full Stack | D20: 4851546652 | E20: gaikwadsrushti.fullstack@gmail.com | F20: Female
A21: 0223CPIT020 | B21: GAJJELA GIRI | C21: ITES | D21: 6604423032 | E21: gajjelagiri.itesites@gmail.com | F21: Male
A22: 0223CPIT021 | B22: GARAPATI GAYATHRI | C22: ITES | D22: 4267924443 | E22: garapatigayathri.itesites@gmail.com | F22: Female
A23: 0223CPIT022 | B23: GOLI SAI LOKESH | C23: Full Stack | D23: 2776428499 | E23: golisailokesh.fullstack@gmail.com | F23: Male
A24: 0223CPIT023 | B24: GURRAM YAMINI | C24: Full Stack | D24: 2344591250 | E24: gurramyamini.fullstack@gmail.com | F24: Female
A25: 0223CPIT024 | B25: HARI OM RAI | C25: Full Stack | D25: 4564000793 | E25: hariomrai.fullstack@gmail.com | F25: Male
... A81: 0223CPIT080 | B81: B Aravind | C81: Full Stack | D81: 2217423855 | E81: baravind.fullstack@gmail.com | F81: Male
A82: 123

Sheet MATCH
A1: S.no | B1: Enrollment number | C1: Name of the Student | D1: Specialization
A2: 1 | B2: 0223CPIT001 | C2: NIKITHA ADULA | D2: ITES
A3: 2 | B3: 0223CPIT002 | C3: ADULA LIKHITHA | D3: Full Stack | G3: Enrollment number | H3: The Enrollment Number is present in What row
A4: 3 | B4: 0223CPIT003 | C4: AKASH RAJPOOT | D4: Full Stack | G4: 0223CPIT005 | H4: =MATCH(G4,$B$2:$B$14,0) -> 5
A5: 4 | B5: 0223CPIT004 | C5: ALOK KUMAR | D5: Full Stack
A6: 5 | B6: 0223CPIT005 | C6: AYUSHMAN SINGH BAGHEL | D6: Full Stack
A7: 6 | B7: 0223CPIT006 | C7: B SANDEEP ROY | D7: ITES
A8: 7 | B8: 0223CPIT007 | C8: B. SRINIVASULU | D8: Full Stack
A9: 8 | B9: 0223CPIT008 | C9: BAIRI PRATHYUSH | D9: Full Stack
A10: 9 | B10: 0223CPIT009 | C10: BANDAPALLI GANGABHAVANI | D10: ITES
A11: 10 | B11: 0223CPIT010 | C11: BURRI VINITHA | D11: Full Stack
A12: 11 | B12: 0223CPIT011 | C12: CHANDRA SAMPATH KUMAR | D12: Full Stack
A13: 12 | B13: 0223CPIT012 | C13: CHINNAKOTLA SURYA TEJA | D13: Full Stack
A14: 13 | B14: 0223CPIT013 | C14: DASARI VIMALA | D14: Full Stack

Sheet BOTHTOGETHERDATA
A1: Enrollment number | B1: Name of the Student | C1: Specialization | D1: MobileNo | E1: Mail IDs | F1: Gender | G1: Name According to Bank
A2: 0223CPIT001 | B2: NIKITHA ADULA | C2: ITES | D2: 6399221384 | E2: nikitha.itesites@gmail.com | F2: Female | G2: =B2 -> NIKITHA ADULA
A3: 0223CPIT002 | B3: ADULA LIKHITHA | C3: Full Stack | D3: 8732960724 | E3: adulalikitha.fullstack@gmail.com | F3: Female | G3: =B3 -> ADULA LIKHITHA
A4: 0223CPIT003 | B4: AKASH RAJPOOT | C4: Full Stack | D4: 3928683138 | E4: akashrajpoot.fullstack@gmail.com | F4: Male | G4: =B4 -> AKASH RAJPOOT
A5: 0223CPIT004 | B5: ALOK KUMAR | C5: Full Stack | D5: 6302977515 | E5: alokkumar.fullstack@gmail.com | F5: Male | G5: =B5 -> ALOK KUMAR
A6: 0223CPIT005 | B6: AYUSHMAN SINGH BAGHEL | C6: Full Stack | D6: 3285643454 | E6: ayushmansinghbaghel.fullstack@gmail.com | F6: Male | G6: =B6 -> AYUSHMAN SINGH BAGHEL
A7: 0223CPIT006 | B7: B SANDEEP ROY | C7: ITES | D7: 6204804746 | E7: bsandeeproy.itesites@gmail.com | F7: Male | G7: =B7 -> B SANDEEP ROY
A8: 0223CPIT007 | B8: B. SRINIVASULU | C8: Full Stack | D8: 8402592334 | E8: bsrinivasulu.fullstack@gmail.com | F8: Male | G8: =B8 -> B. SRINIVASULU
A9: 0223CPIT008 | B9: BAIRI PRATHYUSH | C9: Full Stack | D9: 1770577932 | E9: bairiprathyush.fullstack@gmail.com | F9: Male | G9: =B9 -> BAIRI PRATHYUSH
A10: 0223CPIT009 | B10: BANDAPALLI GANGABHAVANI | C10: ITES | D10: 1087593685 | E10: bandapalligangabhavani.itesites@gmail.com | F10: Female | G10: =B10 -> BANDAPALLI GANGABHAVANI
A11: 0223CPIT010 | B11: BURRI VINITHA | C11: Full Stack | D11: 1693682470 | E11: burrivinitha.fullstack@gmail.com | F11: Female | G11: =B11 -> BURRI VINITHA
A12: 0223CPIT011 | B12: CHANDRA SAMPATH KUMAR | C12: Full Stack | D12: 1821308586 | E12: chandrasampathkumar.fullstack@gmail.com | F12: Male | G12: =B12 -> CHANDRA SAMPATH KUMAR
A13: 0223CPIT012 | B13: CHINNAKOTLA SURYA TEJA | C13: Full Stack | D13: 1683546545 | E13: chinnakotlasuryateja.fullstack@gmail.com | F13: Male | G13: =B13 -> CHINNAKOTLA SURYA TEJA
... A81: 0223CPIT080 | B81: B Aravind | C81: Full Stack | D81: 2217423855 | E81: baravind.fullstack@gmail.com | F81: Male | G81: =B81 -> B Aravind
A82: 123

Sheet INDEXANDMATCH
G6: Enrollment number | H6: Name of the Student | I6: Specialization
G7: 0223CPIT036 | H7: =INDEX(BOTHTOGETHERDATA!$A$2:$G$82,MATCH(G7,BOTHTOGETHERDATA!$A$2:$A$82,0),2) -> MASKA PAVANI | I7: =INDEX(BOTHTOGETHERDATA!$A$2:$G$82,MATCH(G7,BOTHTOGETHERDATA!$A$2:$A$82,0),3) -> ITES
H8: =MATCH(G7,BOTHTOGETHERDATA!$A$2:$A$82,0) -> 36

Sheet Sheet7
